(3375, 3695, 1)
(3375, 27)
Model: "sequential"
_________________________________________________________________
 Layer (type)                Output Shape              Param #
=================================================================
 dense (Dense)               (None, 3695, 4000)        8000
 dense_1 (Dense)             (None, 3695, 256)         1024256
 dense_2 (Dense)             (None, 3695, 27)          6939
=================================================================
Total params: 1,039,195
Trainable params: 1,039,195
Non-trainable params: 0
_________________________________________________________________
None
Epoch 1/10
Traceback (most recent call last):
  File "DEFUNCT_train_cnn.py", line 58, in <module>
    model.fit(x=train_x, y=train_y, batch_size=64, epochs=epc, validation_data=(test_x,test_y),callbacks=[WandbMetricsLogger()])
  File "C:\Users\SS&AL\AppData\Local\Programs\Python\Python37\lib\site-packages\wandb\integration\keras\keras.py", line 174, in new_v2
    return old_v2(*args, **kwargs)
  File "C:\Users\SS&AL\AppData\Local\Programs\Python\Python37\lib\site-packages\wandb\integration\keras\keras.py", line 174, in new_v2
    return old_v2(*args, **kwargs)
  File "C:\Users\SS&AL\AppData\Local\Programs\Python\Python37\lib\site-packages\wandb\integration\keras\keras.py", line 174, in new_v2
    return old_v2(*args, **kwargs)
  File "C:\Users\SS&AL\AppData\Local\Programs\Python\Python37\lib\site-packages\keras\utils\traceback_utils.py", line 70, in error_handler
    raise e.with_traceback(filtered_tb) from None
  File "C:\Users\SS&AL\AppData\Local\Temp\__autograph_generated_file3w3ix31z.py", line 15, in tf__train_function
    retval_ = ag__.converted_call(ag__.ld(step_function), (ag__.ld(self), ag__.ld(iterator)), None, fscope)
ValueError: in user code:
    File "C:\Users\SS&AL\AppData\Local\Programs\Python\Python37\lib\site-packages\keras\engine\training.py", line 1249, in train_function  *
        return step_function(self, iterator)
    File "C:\Users\SS&AL\AppData\Local\Programs\Python\Python37\lib\site-packages\keras\engine\training.py", line 1233, in step_function  **
        outputs = model.distribute_strategy.run(run_step, args=(data,))
    File "C:\Users\SS&AL\AppData\Local\Programs\Python\Python37\lib\site-packages\keras\engine\training.py", line 1222, in run_step  **
        outputs = model.train_step(data)
    File "C:\Users\SS&AL\AppData\Local\Programs\Python\Python37\lib\site-packages\keras\engine\training.py", line 1024, in train_step
        loss = self.compute_loss(x, y, y_pred, sample_weight)
    File "C:\Users\SS&AL\AppData\Local\Programs\Python\Python37\lib\site-packages\keras\engine\training.py", line 1083, in compute_loss
        y, y_pred, sample_weight, regularization_losses=self.losses
    File "C:\Users\SS&AL\AppData\Local\Programs\Python\Python37\lib\site-packages\keras\engine\compile_utils.py", line 265, in __call__
        loss_value = loss_obj(y_t, y_p, sample_weight=sw)
    File "C:\Users\SS&AL\AppData\Local\Programs\Python\Python37\lib\site-packages\keras\losses.py", line 152, in __call__
        losses = call_fn(y_true, y_pred)
    File "C:\Users\SS&AL\AppData\Local\Programs\Python\Python37\lib\site-packages\keras\losses.py", line 284, in call  **
        return ag_fn(y_true, y_pred, **self._fn_kwargs)
    File "C:\Users\SS&AL\AppData\Local\Programs\Python\Python37\lib\site-packages\keras\losses.py", line 2005, in categorical_crossentropy
        y_true, y_pred, from_logits=from_logits, axis=axis
    File "C:\Users\SS&AL\AppData\Local\Programs\Python\Python37\lib\site-packages\keras\backend.py", line 5532, in categorical_crossentropy
        target.shape.assert_is_compatible_with(output.shape)
    ValueError: Shapes (None, 27) and (None, 3695, 27) are incompatible