(3375, 3695, 1)
(3375, 27)
Epoch 1/10
Traceback (most recent call last):
  File "DEFUNCT_train_cnn.py", line 50, in <module>
    model.fit(x=train_x, y=train_y, batch_size=64, epochs=10, validation_data=(test_x,test_y),callbacks=[WandbMetricsLogger()])
  File "C:\Users\SS&AL\AppData\Local\Programs\Python\Python37\lib\site-packages\wandb\integration\keras\keras.py", line 174, in new_v2
    return old_v2(*args, **kwargs)
  File "C:\Users\SS&AL\AppData\Local\Programs\Python\Python37\lib\site-packages\wandb\integration\keras\keras.py", line 174, in new_v2
    return old_v2(*args, **kwargs)
  File "C:\Users\SS&AL\AppData\Local\Programs\Python\Python37\lib\site-packages\wandb\integration\keras\keras.py", line 174, in new_v2
    return old_v2(*args, **kwargs)
  File "C:\Users\SS&AL\AppData\Local\Programs\Python\Python37\lib\site-packages\keras\utils\traceback_utils.py", line 70, in error_handler
    raise e.with_traceback(filtered_tb) from None
  File "C:\Users\SS&AL\AppData\Local\Programs\Python\Python37\lib\site-packages\tensorflow\python\eager\execute.py", line 53, in quick_execute
    inputs, attrs, num_outputs)
tensorflow.python.framework.errors_impl.InvalidArgumentError: Graph execution error:
Detected at node 'sparse_categorical_crossentropy/SparseSoftmaxCrossEntropyWithLogits/SparseSoftmaxCrossEntropyWithLogits' defined at (most recent call last):
    File "DEFUNCT_train_cnn.py", line 50, in <module>
      model.fit(x=train_x, y=train_y, batch_size=64, epochs=10, validation_data=(test_x,test_y),callbacks=[WandbMetricsLogger()])
    File "C:\Users\SS&AL\AppData\Local\Programs\Python\Python37\lib\site-packages\wandb\integration\keras\keras.py", line 174, in new_v2
      return old_v2(*args, **kwargs)
    File "C:\Users\SS&AL\AppData\Local\Programs\Python\Python37\lib\site-packages\wandb\integration\keras\keras.py", line 174, in new_v2
      return old_v2(*args, **kwargs)
    File "C:\Users\SS&AL\AppData\Local\Programs\Python\Python37\lib\site-packages\wandb\integration\keras\keras.py", line 174, in new_v2
      return old_v2(*args, **kwargs)
    File "C:\Users\SS&AL\AppData\Local\Programs\Python\Python37\lib\site-packages\keras\utils\traceback_utils.py", line 65, in error_handler
      return fn(*args, **kwargs)
    File "C:\Users\SS&AL\AppData\Local\Programs\Python\Python37\lib\site-packages\keras\engine\training.py", line 1650, in fit
      tmp_logs = self.train_function(iterator)
    File "C:\Users\SS&AL\AppData\Local\Programs\Python\Python37\lib\site-packages\keras\engine\training.py", line 1249, in train_function
      return step_function(self, iterator)
    File "C:\Users\SS&AL\AppData\Local\Programs\Python\Python37\lib\site-packages\keras\engine\training.py", line 1233, in step_function
      outputs = model.distribute_strategy.run(run_step, args=(data,))
    File "C:\Users\SS&AL\AppData\Local\Programs\Python\Python37\lib\site-packages\keras\engine\training.py", line 1222, in run_step
      outputs = model.train_step(data)
    File "C:\Users\SS&AL\AppData\Local\Programs\Python\Python37\lib\site-packages\keras\engine\training.py", line 1024, in train_step
      loss = self.compute_loss(x, y, y_pred, sample_weight)
    File "C:\Users\SS&AL\AppData\Local\Programs\Python\Python37\lib\site-packages\keras\engine\training.py", line 1083, in compute_loss
      y, y_pred, sample_weight, regularization_losses=self.losses
    File "C:\Users\SS&AL\AppData\Local\Programs\Python\Python37\lib\site-packages\keras\engine\compile_utils.py", line 265, in __call__
      loss_value = loss_obj(y_t, y_p, sample_weight=sw)
    File "C:\Users\SS&AL\AppData\Local\Programs\Python\Python37\lib\site-packages\keras\losses.py", line 152, in __call__
      losses = call_fn(y_true, y_pred)
    File "C:\Users\SS&AL\AppData\Local\Programs\Python\Python37\lib\site-packages\keras\losses.py", line 284, in call
      return ag_fn(y_true, y_pred, **self._fn_kwargs)
    File "C:\Users\SS&AL\AppData\Local\Programs\Python\Python37\lib\site-packages\keras\losses.py", line 2103, in sparse_categorical_crossentropy
      axis=axis,
    File "C:\Users\SS&AL\AppData\Local\Programs\Python\Python37\lib\site-packages\keras\backend.py", line 5634, in sparse_categorical_crossentropy
      labels=target, logits=output
Node: 'sparse_categorical_crossentropy/SparseSoftmaxCrossEntropyWithLogits/SparseSoftmaxCrossEntropyWithLogits'
logits and labels must have the same first dimension, got logits shape [64,27] and labels shape [1728]
	 [[{{node sparse_categorical_crossentropy/SparseSoftmaxCrossEntropyWithLogits/SparseSoftmaxCrossEntropyWithLogits}}]] [Op:__inference_train_function_1109]